Workbook

Sheet sample
A1: objID | B1: ra | C1: dec | D1: z | E1: Rproj | F1: Vrad | G1: u | H1: g | I1: r | J1: i | K1: zmag | L1: u-g | M1: u-r | N1: u-i | O1: u-z | P1: g-r | Q1: g-i | R1: g-z | S1: r-i | T1: r-z | U1: i-z
A2: 1.2376623e+18 | B2: 235.65648 | C2: 35.854315 | D2: 0.000108371 | E2: 2.919416 | F2: 32.5113 | G2: 21.56638 | H2: 19.52135 | I2: 18.16634 | J2: 17.50483 | K2: 17.12782 | L2: =G2-H2 -> 2.04503 | M2: =G2-I2 -> 3.40004 | N2: =G2-J2 -> 4.06155 | O2: =G2-K2 -> 4.43856 | P2: =H2-I2 -> 1.35501 | Q2: =H2-J2 -> 2.01652 | R2: =H2-K2 -> 2.39353 | S2: =I2-J2 -> 0.66151 | T2: =I2-K2 -> 1.03852 | U2: =J2-K2 -> 0.37701
A3: 1.2376625e+18 | B3: 236.2748 | C3: 35.890829 | D3: 0.006308075 | E3: 1.1865287 | F3: 1892.4225 | G3: 17.00738 | H3: 16.28332 | I3: 16.13911 | J3: 16.18876 | K3: 16.12078 | L3: =G3-H3 -> 0.72406 | M3: =G3-I3 -> 0.86827 | N3: =G3-J3 -> 0.81862 | O3: =G3-K3 -> 0.8866 | P3: =H3-I3 -> 0.14421 | Q3: =H3-J3 -> 0.09456 | R3: =H3-K3 -> 0.16254 | S3: =I3-J3 -> -0.04965 | T3: =I3-K3 -> 0.01833 | U3: =J3-K3 -> 0.06798
A4: 1.2376625e+18 | B4: 236.21743 | C4: 36.479334 | D4: 0.01116591 | E4: 1.9998958 | F4: 3349.773 | G4: 17.23711 | H4: 16.12204 | I4: 15.70031 | J4: 15.54396 | K4: 15.42692 | L4: =G4-H4 -> 1.11507 | M4: =G4-I4 -> 1.5368 | N4: =G4-J4 -> 1.69315 | O4: =G4-K4 -> 1.81019 | P4: =H4-I4 -> 0.42173 | Q4: =H4-J4 -> 0.57808 | R4: =H4-K4 -> 0.69512 | S4: =I4-J4 -> 0.15635 | T4: =I4-K4 -> 0.27339 | U4: =J4-K4 -> 0.11704
A5: 1.2376625e+18 | B5: 236.4412 | C5: 36.028097 | D5: 0.01141854 | E5: 0.95808712 | F5: 3425.562 | G5: 17.51097 | H5: 16.49517 | I5: 16.14774 | J5: 15.93395 | K5: 15.88657 | L5: =G5-H5 -> 1.0158 | M5: =G5-I5 -> 1.36323 | N5: =G5-J5 -> 1.57702 | O5: =G5-K5 -> 1.6244 | P5: =H5-I5 -> 0.34743 | Q5: =H5-J5 -> 0.56122 | R5: =H5-K5 -> 0.6086 | S5: =I5-J5 -> 0.21379 | T5: =I5-K5 -> 0.26117 | U5: =J5-K5 -> 0.04738
A6: 1.2376625e+18 | B6: 236.2044 | C6: 36.563143 | D6: 0.03872261 | E6: 2.4549954 | F6: 11616.783 | G6: 19.35775 | H6: 18.03697 | I6: 17.53016 | J6: 17.28015 | K6: 17.14247 | L6: =G6-H6 -> 1.32078 | M6: =G6-I6 -> 1.82759 | N6: =G6-J6 -> 2.0776 | O6: =G6-K6 -> 2.21528 | P6: =H6-I6 -> 0.50681 | Q6: =H6-J6 -> 0.75682 | R6: =H6-K6 -> 0.8945 | S6: =I6-J6 -> 0.25001 | T6: =I6-K6 -> 0.38769 | U6: =J6-K6 -> 0.13768
A7: 1.2376623e+18 | B7: 235.95322 | C7: 35.634052 | D7: 0.04851187 | E7: 2.8672774 | F7: 14553.561 | G7: 18.61084 | H7: 17.50902 | I7: 17.10076 | J7: 16.83978 | K7: 16.66014 | L7: =G7-H7 -> 1.10182 | M7: =G7-I7 -> 1.51008 | N7: =G7-J7 -> 1.77106 | O7: =G7-K7 -> 1.9507 | P7: =H7-I7 -> 0.40826 | Q7: =H7-J7 -> 0.66924 | R7: =H7-K7 -> 0.84888 | S7: =I7-J7 -> 0.26098 | T7: =I7-K7 -> 0.44062 | U7: =J7-K7 -> 0.17964
A8: 1.2376615e+18 | B8: 236.42283 | C8: 35.660888 | D8: 0.05498169 | E8: 2.5412467 | F8: 16494.507 | G8: 19.13241 | H8: 17.62904 | I8: 17.08061 | J8: 16.8184 | K8: 16.59398 | L8: =G8-H8 -> 1.50337 | M8: =G8-I8 -> 2.0518 | N8: =G8-J8 -> 2.31401 | O8: =G8-K8 -> 2.53843 | P8: =H8-I8 -> 0.54843 | Q8: =H8-J8 -> 0.81064 | R8: =H8-K8 -> 1.03506 | S8: =I8-J8 -> 0.26221 | T8: =I8-K8 -> 0.48663 | U8: =J8-K8 -> 0.22442
A9: 1.2376615e+18 | B9: 236.4388 | C9: 35.659931 | D9: 0.0551876 | E9: 2.5682362 | F9: 16556.28 | G9: 17.60702 | H9: 15.61395 | I9: 14.70474 | J9: 14.26028 | K9: 13.9209 | L9: =G9-H9 -> 1.99307 | M9: =G9-I9 -> 2.90228 | N9: =G9-J9 -> 3.34674 | O9: =G9-K9 -> 3.68612 | P9: =H9-I9 -> 0.90921 | Q9: =H9-J9 -> 1.35367 | R9: =H9-K9 -> 1.69305 | S9: =I9-J9 -> 0.44446 | T9: =I9-K9 -> 0.78384 | U9: =J9-K9 -> 0.33938
A10: 1.2376615e+18 | B10: 236.4388 | C10: 35.659931 | D10: 0.05523921 | E10: 2.5682362 | F10: 16571.763 | G10: 17.60702 | H10: 15.61395 | I10: 14.70474 | J10: 14.26028 | K10: 13.9209 | L10: =G10-H10 -> 1.99307 | M10: =G10-I10 -> 2.90228 | N10: =G10-J10 -> 3.34674 | O10: =G10-K10 -> 3.68612 | P10: =H10-I10 -> 0.90921 | Q10: =H10-J10 -> 1.35367 | R10: =H10-K10 -> 1.69305 | S10: =I10-J10 -> 0.44446 | T10: =I10-K10 -> 0.78384 | U10: =J10-K10 -> 0.33938
A11: 1.2376625e+18 | B11: 236.28331 | C11: 36.184873 | D11: 0.05844347 | E11: 0.43827063 | F11: 17533.041 | G11: 18.20866 | H11: 16.87177 | I11: 16.25138 | J11: 15.9163 | K11: 15.71328 | L11: =G11-H11 -> 1.33689 | M11: =G11-I11 -> 1.95728 | N11: =G11-J11 -> 2.29236 | O11: =G11-K11 -> 2.49538 | P11: =H11-I11 -> 0.62039 | Q11: =H11-J11 -> 0.95547 | R11: =H11-K11 -> 1.15849 | S11: =I11-J11 -> 0.33508 | T11: =I11-K11 -> 0.5381 | U11: =J11-K11 -> 0.20302
A12: 1.2376625e+18 | B12: 236.24143 | C12: 36.06883 | D12: 0.0599989 | E12: 0.22015405 | F12: 17999.67 | G12: 18.47967 | H12: 16.59626 | I12: 15.71089 | J12: 15.2984 | K12: 14.95353 | L12: =G12-H12 -> 1.88341 | M12: =G12-I12 -> 2.76878 | N12: =G12-J12 -> 3.18127 | O12: =G12-K12 -> 3.52614 | P12: =H12-I12 -> 0.88537 | Q12: =H12-J12 -> 1.29786 | R12: =H12-K12 -> 1.64273 | S12: =I12-J12 -> 0.41249 | T12: =I12-K12 -> 0.75736 | U12: =J12-K12 -> 0.34487
A13: 1.2376625e+18 | B13: 236.261 | C13: 36.156339 | D13: 0.06039927 | E13: 0.2613134 | F13: 18119.781 | G13: 18.3734 | H13: 16.41381 | I13: 15.52388 | J13: 15.09743 | K13: 14.7649 | L13: =G13-H13 -> 1.95959 | M13: =G13-I13 -> 2.84952 | N13: =G13-J13 -> 3.27597 | O13: =G13-K13 -> 3.6085 | P13: =H13-I13 -> 0.88993 | Q13: =H13-J13 -> 1.31638 | R13: =H13-K13 -> 1.64891 | S13: =I13-J13 -> 0.42645 | T13: =I13-K13 -> 0.75898 | U13: =J13-K13 -> 0.33253
... A475: 1.2376625e+18 | B475: 235.98914 | C475: 36.504567 | D475: 1.530724 | E475: 2.4070626 | F475: 459217.2 | G475: 24.58632 | H475: 23.0649 | I475: 21.77084 | J475: 20.75945 | K475: 19.92884 | L475: =G475-H475 -> 1.52142 | M475: =G475-I475 -> 2.81548 | N475: =G475-J475 -> 3.82687 | O475: =G475-K475 -> 4.65748 | P475: =H475-I475 -> 1.29406 | Q475: =H475-J475 -> 2.30545 | R475: =H475-K475 -> 3.13606 | S475: =I475-J475 -> 1.01139 | T475: =I475-K475 -> 1.842 | U475: =J475-K475 -> 0.83061

Sheet standard
A1: objID | B1: ra | C1: dec | D1: z | E1: u-g | F1: u-r | G1: u-i | H1: u-z | I1: g-r | J1: g-i | K1: g-z | L1: r-i | M1: r-z | N1: i-z | P1: ra | Q1: dec | R1: z | S1: u-g | T1: u-r | U1: u-i | V1: u-z | W1: g-r | X1: g-i | Y1: g-z | Z1: r-i | AA1: r-z | AB1: i-z
A2: 1.2376623e+18 | B2: 235.65648 | C2: 35.854315 | D2: 0.000108371 | E2: 2.04503 | F2: 3.40004 | G2: 4.06155 | H2: 4.43856 | I2: 1.35501 | J2: 2.01652 | K2: 2.39353 | L2: 0.66151 | M2: 1.03852 | N2: 0.37701 | P2: =(B2-B$476)/B$477 -> -1.8764745 | Q2: =(C2-C$476)/C$477 -> -0.8253689 | R2: =(D2-D$476)/D$477 -> -1.3460069 | S2: =(E2-E$476)/E$477 -> 0.23572514 | T2: =(F2-F$476)/F$477 -> 0.23160015 | U2: =(G2-G$476)/G$477 -> 0.17097255 | V2: =(H2-H$476)/H$477 -> 0.13379368 | W2: =(I2-I$476)/I$477 -> 0.041105992 | ... AB2: =(N2-N$476)/N$477 -> -0.20122514
A3: 1.2376625e+18 | B3: 236.2748 | C3: 35.890829 | D3: 0.006308075 | E3: 0.72406 | F3: 0.86827 | G3: 0.81862 | H3: 0.8866 | I3: 0.14421 | J3: 0.09456 | K3: 0.16254 | L3: -0.04965 | M3: 0.01833 | N3: 0.06798 | P3: =(B3-B$476)/B$477 -> 0.025952075 | Q3: =(C3-C$476)/C$477 -> -0.69610721 | R3: =(D3-D$476)/D$477 -> -1.321723 | S3: =(E3-E$476)/E$477 -> -1.0645817 | T3: =(F3-F$476)/F$477 -> -2.0204593 | U3: =(G3-G$476)/G$477 -> -2.4543639 | V3: =(H3-H$476)/H$477 -> -2.5848729 | W3: =(I3-I$476)/I$477 -> -2.3409348 | ... AB3: =(N3-N$476)/N$477 -> -1.9100529
A4: 1.2376625e+18 | B4: 236.21743 | C4: 36.479334 | D4: 0.01116591 | E4: 1.11507 | F4: 1.5368 | G4: 1.69315 | H4: 1.81019 | I4: 0.42173 | J4: 0.57808 | K4: 0.69512 | L4: 0.15635 | M4: 0.27339 | N4: 0.11704 | P4: =(B4-B$476)/B$477 -> -0.15056205 | Q4: =(C4-C$476)/C$477 -> 1.3872348 | R4: =(D4-D$476)/D$477 -> -1.3026951 | S4: =(E4-E$476)/E$477 -> -0.67968801 | T4: =(F4-F$476)/F$477 -> -1.4257886 | U4: =(G4-G$476)/G$477 -> -1.7463821 | V4: =(H4-H$476)/H$477 -> -1.877958 | W4: =(I4-I$476)/I$477 -> -1.794962 | ... AB4: =(N4-N$476)/N$477 -> -1.6387683
A5: 1.2376625e+18 | B5: 236.4412 | C5: 36.028097 | D5: 0.01141854 | E5: 1.0158 | F5: 1.36323 | G5: 1.57702 | H5: 1.6244 | I5: 0.34743 | J5: 0.56122 | K5: 0.6086 | L5: 0.21379 | M5: 0.26117 | N5: 0.04738 | P5: =(B5-B$476)/B$477 -> 0.5379261 | Q5: =(C5-C$476)/C$477 -> -0.21017048 | R5: =(D5-D$476)/D$477 -> -1.3017055 | S5: =(E5-E$476)/E$477 -> -0.77740518 | T5: =(F5-F$476)/F$477 -> -1.5801826 | U5: =(G5-G$476)/G$477 -> -1.8403959 | V5: =(H5-H$476)/H$477 -> -2.0201615 | W5: =(I5-I$476)/I$477 -> -1.9411344 | ... AB5: =(N5-N$476)/N$477 -> -2.0239637
A6: 1.2376625e+18 | B6: 236.2044 | C6: 36.563143 | D6: 0.03872261 | E6: 1.32078 | F6: 1.82759 | G6: 2.0776 | H6: 2.21528 | I6: 0.50681 | J6: 0.75682 | K6: 0.8945 | L6: 0.25001 | M6: 0.38769 | N6: 0.13768 | P6: =(B6-B$476)/B$477 -> -0.19065232 | Q6: =(C6-C$476)/C$477 -> 1.6839236 | R6: =(D6-D$476)/D$477 -> -1.1947568 | S6: =(E6-E$476)/E$477 -> -0.47719582 | T6: =(F6-F$476)/F$477 -> -1.1671252 | U6: =(G6-G$476)/G$477 -> -1.4351479 | V6: =(H6-H$476)/H$477 -> -1.5679025 | W6: =(I6-I$476)/I$477 -> -1.6275817 | ... AB6: =(N6-N$476)/N$477 -> -1.5246363
A7: 1.2376623e+18 | B7: 235.95322 | C7: 35.634052 | D7: 0.04851187 | E7: 1.10182 | F7: 1.51008 | G7: 1.77106 | H7: 1.9507 | I7: 0.40826 | J7: 0.66924 | K7: 0.84888 | L7: 0.26098 | M7: 0.44062 | N7: 0.17964 | P7: =(B7-B$476)/B$477 -> -0.96347466 | Q7: =(C7-C$476)/C$477 -> -1.6051128 | R7: =(D7-D$476)/D$477 -> -1.1564127 | S7: =(E7-E$476)/E$477 -> -0.69273075 | T7: =(F7-F$476)/F$477 -> -1.4495566 | U7: =(G7-G$476)/G$477 -> -1.6833095 | V7: =(H7-H$476)/H$477 -> -1.7704118 | W7: =(I7-I$476)/I$477 -> -1.8214619 | ... AB7: =(N7-N$476)/N$477 -> -1.2926122
A8: 1.2376615e+18 | B8: 236.42283 | C8: 35.660888 | D8: 0.05498169 | E8: 1.50337 | F8: 2.0518 | G8: 2.31401 | H8: 2.53843 | I8: 0.54843 | J8: 0.81064 | K8: 1.03506 | L8: 0.26221 | M8: 0.48663 | N8: 0.22442 | P8: =(B8-B$476)/B$477 -> 0.48140589 | Q8: =(C8-C$476)/C$477 -> -1.5101118 | R8: =(D8-D$476)/D$477 -> -1.1310707 | S8: =(E8-E$476)/E$477 -> -0.29746197 | T8: =(F8-F$476)/F$477 -> -0.96768597 | U8: =(G8-G$476)/G$477 -> -1.2437606 | V8: =(H8-H$476)/H$477 -> -1.3205639 | W8: =(I8-I$476)/I$477 -> -1.5457015 | ... AB8: =(N8-N$476)/N$477 -> -1.0449945
A9: 1.2376615e+18 | B9: 236.4388 | C9: 35.659931 | D9: 0.0551876 | E9: 1.99307 | F9: 2.90228 | G9: 3.34674 | H9: 3.68612 | I9: 0.90921 | J9: 1.35367 | K9: 1.69305 | L9: 0.44446 | M9: 0.78384 | N9: 0.33938 | P9: =(B9-B$476)/B$477 -> 0.53054186 | Q9: =(C9-C$476)/C$477 -> -1.5134996 | R9: =(D9-D$476)/D$477 -> -1.1302642 | S9: =(E9-E$476)/E$477 -> 0.18457792 | T9: =(F9-F$476)/F$477 -> -0.2111672 | U9: =(G9-G$476)/G$477 -> -0.40770684 | V9: =(H9-H$476)/H$477 -> -0.44212312 | W9: =(I9-I$476)/I$477 -> -0.83592887 | ... AB9: =(N9-N$476)/N$477 -> -0.40930587
A10: 1.2376615e+18 | B10: 236.4388 | C10: 35.659931 | D10: 0.05523921 | E10: 1.99307 | F10: 2.90228 | G10: 3.34674 | H10: 3.68612 | I10: 0.90921 | J10: 1.35367 | K10: 1.69305 | L10: 0.44446 | M10: 0.78384 | N10: 0.33938 | P10: =(B10-B$476)/B$477 -> 0.53054186 | Q10: =(C10-C$476)/C$477 -> -1.5134996 | R10: =(D10-D$476)/D$477 -> -1.130062 | S10: =(E10-E$476)/E$477 -> 0.18457792 | T10: =(F10-F$476)/F$477 -> -0.2111672 | U10: =(G10-G$476)/G$477 -> -0.40770684 | V10: =(H10-H$476)/H$477 -> -0.44212312 | W10: =(I10-I$476)/I$477 -> -0.83592887 | ... AB10: =(N10-N$476)/N$477 -> -0.40930587
A11: 1.2376625e+18 | B11: 236.28331 | C11: 36.184873 | D11: 0.05844347 | E11: 1.33689 | F11: 1.95728 | G11: 2.29236 | H11: 2.49538 | I11: 0.62039 | J11: 0.95547 | K11: 1.15849 | L11: 0.33508 | M11: 0.5381 | N11: 0.20302 | P11: =(B11-B$476)/B$477 -> 0.052135363 | Q11: =(C11-C$476)/C$477 -> 0.3448257 | R11: =(D11-D$476)/D$477 -> -1.1175111 | S11: =(E11-E$476)/E$477 -> -0.46133782 | T11: =(F11-F$476)/F$477 -> -1.0517634 | U11: =(G11-G$476)/G$477 -> -1.2612875 | V11: =(H11-H$476)/H$477 -> -1.3535143 | W11: =(I11-I$476)/I$477 -> -1.4041326 | ... AB11: =(N11-N$476)/N$477 -> -1.163329
A12: 1.2376625e+18 | B12: 236.24143 | C12: 36.06883 | D12: 0.0599989 | E12: 1.88341 | F12: 2.76878 | G12: 3.18127 | H12: 3.52614 | I12: 0.88537 | J12: 1.29786 | K12: 1.64273 | L12: 0.41249 | M12: 0.75736 | N12: 0.34487 | P12: =(B12-B$476)/B$477 -> -0.07671964 | Q12: =(C12-C$476)/C$477 -> -0.065973289 | R12: =(D12-D$476)/D$477 -> -1.1114185 | S12: =(E12-E$476)/E$477 -> 0.076633274 | T12: =(F12-F$476)/F$477 -> -0.32991809 | U12: =(G12-G$476)/G$477 -> -0.54166422 | V12: =(H12-H$476)/H$477 -> -0.56457165 | W12: =(I12-I$476)/I$477 -> -0.88282997 | ... AB12: =(N12-N$476)/N$477 -> -0.3789481
A13: 1.2376625e+18 | B13: 236.261 | C13: 36.156339 | D13: 0.06039927 | E13: 1.95959 | F13: 2.84952 | G13: 3.27597 | H13: 3.6085 | I13: 0.88993 | J13: 1.31638 | K13: 1.64891 | L13: 0.42645 | M13: 0.75898 | N13: 0.33253 | P13: =(B13-B$476)/B$477 -> -0.016507309 | Q13: =(C13-C$476)/C$477 -> 0.24381368 | R13: =(D13-D$476)/D$477 -> -1.1098503 | S13: =(E13-E$476)/E$477 -> 0.15162163 | T13: =(F13-F$476)/F$477 -> -0.25809827 | U13: =(G13-G$476)/G$477 -> -0.46499918 | V13: =(H13-H$476)/H$477 -> -0.50153339 | W13: =(I13-I$476)/I$477 -> -0.87385895 | ... AB13: =(N13-N$476)/N$477 -> -0.44718398
... A475: 1.2376625e+18 | B475: 235.98914 | C475: 36.504567 | D475: 1.530724 | E475: 1.52142 | F475: 2.81548 | G475: 3.82687 | H475: 4.65748 | I475: 1.29406 | J475: 2.30545 | K475: 3.13606 | L475: 1.01139 | M475: 1.842 | N475: 0.83061 | P475: =(B475-B$476)/B$477 -> -0.85295719 | Q475: =(C475-C$476)/C$477 -> 1.4765611 | R475: =(D475-D$476)/D$477 -> 4.6493435 | S475: =(E475-E$476)/E$477 -> -0.27969432 | T475: =(F475-F$476)/F$477 -> -0.28837752 | U475: =(G475-G$476)/G$477 -> -0.019014272 | V475: =(H475-H$476)/H$477 -> 0.30135482 | W475: =(I475-I$476)/I$477 -> -0.078802654 | ... AB475: =(N475-N$476)/N$477 -> 2.3070242
A476: mean | B476: =AVERAGE(B2:B475) -> 236.26637 | C476: =AVERAGE(C2:C475) -> 36.087466 | D476: =AVERAGE(D2:D475) -> 0.34374454 | E476: =AVERAGE(E2:E475) -> 1.8055589 | F476: =AVERAGE(F2:F475) -> 3.1396746 | G476: =AVERAGE(G2:G475) -> 3.8503573 | H476: =AVERAGE(H2:H475) -> 4.2637575 | I476: =AVERAGE(I2:I475) -> 1.3341157 | ... N476: =AVERAGE(N2:N475) -> 0.41340021 | P476: =AVERAGE(P2:P475) -> -4.3297058e-13 | Q476: =AVERAGE(Q2:Q475) -> 1.0747146e-14 | R476: =AVERAGE(R2:R475) -> -2.2110771e-16 | S476: =AVERAGE(S2:S475) -> 1.7906445e-15 | T476: =AVERAGE(T2:T475) -> 6.6894451e-16 | U476: =AVERAGE(U2:U475) -> -1.9081153e-15 | V476: =AVERAGE(V2:V475) -> -1.1680764e-15 | W476: =AVERAGE(W2:W475) -> -2.0719186e-15 | ... AB476: =AVERAGE(AB2:AB475) -> 8.0573148e-17
A477: stdv | B477: =STDEV(B2:B475) -> 0.32501649 | C477: =STDEV(C2:C475) -> 0.28248122 | D477: =STDEV(D2:D475) -> 0.25530044 | E477: =STDEV(E2:E475) -> 1.015891 | F477: =STDEV(F2:F475) -> 1.1242021 | G477: =STDEV(G2:G475) -> 1.2352436 | H477: =STDEV(H2:H475) -> 1.3065082 | I477: =STDEV(I2:I475) -> 0.50830363 | ... N477: =STDEV(N2:N475) -> 0.18084327 | P477: =STDEV(P2:P475) -> 1 | Q477: =STDEV(Q2:Q475) -> 1 | R477: =STDEV(R2:R475) -> 1 | S477: =STDEV(S2:S475) -> 1 | T477: =STDEV(T2:T475) -> 1 | U477: =STDEV(U2:U475) -> 1 | V477: =STDEV(V2:V475) -> 1 | W477: =STDEV(W2:W475) -> 1 | ... AB477: =STDEV(AB2:AB475) -> 1

Sheet eigen
A1: Covariance Matrix | P1: Identity
B2: ra | C2: dec | D2: z | E2: u-g | F2: u-r | G2: u-i | H2: u-z | I2: g-r | J2: g-i | K2: g-z | L2: r-i | M2: r-z | N2: i-z
A3: ra | B3: 1 | C3: 0.086772465 | D3: 0.10415228 | E3: 0.053015152 | F3: 0.089529422 | G3: 0.11712576 | H3: 0.12970701 | I3: 0.092054328 | J3: 0.1160077 | K3: 0.12551665 | L3: 0.1314098 | M3: 0.14030105 | N3: 0.13704917 | P3: 1 | Q3: 0 | R3: 0 | S3: 0 | T3: 0 | U3: 0 | V3: 0 | W3: 0 | X3: 0 | Y3: 0 | Z3: 0 | AA3: 0 | AB3: 0
A4: dec | B4: 0.086772465 | C4: 1 | D4: 0.087659069 | E4: -0.076947304 | F4: -0.059238845 | G4: -0.030776704 | H4: -0.015172951 | I4: 0.022769146 | J4: 0.051288644 | K4: 0.063348603 | L4: 0.085298238 | M4: 0.095362441 | N4: 0.10060171 | P4: 0 | Q4: 1 | R4: 0 | S4: 0 | T4: 0 | U4: 0 | V4: 0 | W4: 0 | X4: 0 | Y4: 0 | Z4: 0 | AA4: 0 | AB4: 0
A5: z | B5: 0.10415228 | C5: 0.087659069 | D5: 1 | E5: -0.15686805 | F5: 0.17283514 | G5: 0.40817009 | H5: 0.48920373 | I5: 0.69577012 | J5: 0.84756561 | K5: 0.86696666 | L5: 0.92488306 | M5: 0.9069727 | N5: 0.74627704 | P5: 0 | Q5: 0 | R5: 1 | S5: 0 | T5: 0 | U5: 0 | V5: 0 | W5: 0 | X5: 0 | Y5: 0 | Z5: 0 | AA5: 0 | AB5: 0
A6: u-g | B6: 0.053015152 | C6: -0.076947304 | D6: -0.15686805 | E6: 1 | F6: 0.89201977 | G6: 0.77495703 | H6: 0.71224645 | I6: -0.025733636 | J6: -0.074889631 | K6: -0.092651106 | L6: -0.13594677 | M6: -0.14731593 | N6: -0.14766876 | P6: 0 | Q6: 0 | R6: 0 | S6: 1 | T6: 0 | U6: 0 | V6: 0 | W6: 0 | X6: 0 | Y6: 0 | Z6: 0 | AA6: 0 | AB6: 0
A7: u-r | B7: 0.089529422 | C7: -0.059238845 | D7: 0.17283514 | E7: 0.89201977 | F7: 1 | G7: 0.96401846 | H7: 0.92942105 | I7: 0.42889179 | J7: 0.36352858 | K7: 0.33451519 | L7: 0.19875917 | M7: 0.18368752 | N7: 0.12993878 | P7: 0 | Q7: 0 | R7: 0 | S7: 0 | T7: 1 | U7: 0 | V7: 0 | W7: 0 | X7: 0 | Y7: 0 | Z7: 0 | AA7: 0 | AB7: 0
A8: u-i | B8: 0.11712576 | C8: -0.030776704 | D8: 0.40817009 | E8: 0.77495703 | F8: 0.96401846 | G8: 1 | H8: 0.9914411 | I8: 0.58327287 | J8: 0.57220287 | K8: 0.55161007 | L8: 0.45213895 | M8: 0.43136648 | N8: 0.33223412 | P8: 0 | Q8: 0 | R8: 0 | S8: 0 | T8: 0 | U8: 1 | V8: 0 | W8: 0 | X8: 0 | Y8: 0 | Z8: 0 | AA8: 0 | AB8: 0
A9: u-z | B9: 0.12970701 | C9: -0.015172951 | D9: 0.48920373 | E9: 0.71224645 | F9: 0.92942105 | G9: 0.9914411 | H9: 1 | I9: 0.63208744 | J9: 0.64007297 | K9: 0.6329198 | L9: 0.53666854 | M9: 0.53346507 | N9: 0.45252938 | P9: 0 | Q9: 0 | R9: 0 | S9: 0 | T9: 0 | U9: 0 | V9: 1 | W9: 0 | X9: 0 | Y9: 0 | Z9: 0 | AA9: 0 | AB9: 0
A10: g-r | B10: 0.092054328 | C10: 0.022769146 | D10: 0.69577012 | E10: -0.025733636 | F10: 0.42889179 | G10: 0.58327287 | H10: 0.63208744 | I10: 1 | J10: 0.95368059 | K10: 0.92501035 | L10: 0.71129255 | M10: 0.70068128 | N10: 0.58251174 | P10: 0 | Q10: 0 | R10: 0 | S10: 0 | T10: 0 | U10: 0 | V10: 0 | W10: 1 | X10: 0 | Y10: 0 | Z10: 0 | AA10: 0 | AB10: 0
A11: 6 | B11: 0.1160077 | C11: 0.051288644 | D11: 0.84756561 | E11: -0.074889631 | F11: 0.36352858 | G11: 0.57220287 | H11: 0.64007297 | I11: 0.95368059 | J11: 1 | K11: 0.99055625 | L11: 0.88979188 | M11: 0.8717699 | N11: 0.71581665 | P11: 0 | Q11: 0 | R11: 0 | S11: 0 | T11: 0 | U11: 0 | V11: 0 | W11: 0 | X11: 1 | Y11: 0 | Z11: 0 | AA11: 0 | AB11: 0
A12: g-z | B12: 0.12551665 | C12: 0.063348603 | D12: 0.86696666 | E12: -0.092651106 | F12: 0.33451519 | G12: 0.55161007 | H12: 0.6329198 | I12: 0.92501035 | J12: 0.99055625 | K12: 1 | L12: 0.91122043 | M12: 0.91921627 | N12: 0.80479682 | P12: 0 | Q12: 0 | R12: 0 | S12: 0 | T12: 0 | U12: 0 | V12: 0 | W12: 0 | X12: 0 | Y12: 1 | Z12: 0 | AA12: 0 | AB12: 0
A13: r-i | B13: 0.1314098 | C13: 0.085298238 | D13: 0.92488306 | E13: -0.13594677 | F13: 0.19875917 | G13: 0.45213895 | H13: 0.53666854 | I13: 0.71129255 | J13: 0.88979188 | K13: 0.91122043 | L13: 1 | M13: 0.97398802 | N13: 0.78886039 | P13: 0 | Q13: 0 | R13: 0 | S13: 0 | T13: 0 | U13: 0 | V13: 0 | W13: 0 | X13: 0 | Y13: 0 | Z13: 1 | AA13: 0 | AB13: 0
A14: r-z | B14: 0.14030105 | C14: 0.095362441 | D14: 0.9069727 | E14: -0.14731593 | F14: 0.18368752 | G14: 0.43136648 | H14: 0.53346507 | I14: 0.70068128 | J14: 0.8717699 | K14: 0.91921627 | L14: 0.97398802 | M14: 1 | N14: 0.90760238 | P14: 0 | Q14: 0 | R14: 0 | S14: 0 | T14: 0 | U14: 0 | V14: 0 | W14: 0 | X14: 0 | Y14: 0 | Z14: 0 | AA14: 1 | AB14: 0
A15: i-z | B15: 0.13704917 | C15: 0.10060171 | D15: 0.74627704 | E15: -0.14766876 | F15: 0.12993878 | G15: 0.33223412 | H15: 0.45252938 | I15: 0.58251174 | J15: 0.71581665 | K15: 0.80479682 | L15: 0.78886039 | M15: 0.90760238 | N15: 1 | P15: 0 | Q15: 0 | R15: 0 | S15: 0 | T15: 0 | U15: 0 | V15: 0 | W15: 0 | X15: 0 | Y15: 0 | Z15: 0 | AA15: 0 | AB15: 1
A17: initial eigen | B17: 0
P18: =B3-eigen!$B$17*eigen!P3 -> 1 | Q18: =C3-eigen!$B$17*eigen!Q3 -> 0.086772465 | R18: =D3-eigen!$B$17*eigen!R3 -> 0.10415228 | S18: =E3-eigen!$B$17*eigen!S3 -> 0.053015152 | T18: =F3-eigen!$B$17*eigen!T3 -> 0.089529422 | U18: =G3-eigen!$B$17*eigen!U3 -> 0.11712576 | V18: =H3-eigen!$B$17*eigen!V3 -> 0.12970701 | W18: =I3-eigen!$B$17*eigen!W3 -> 0.092054328 | ... AB18: =N3-eigen!$B$17*eigen!AB3 -> 0.13704917
A19: det | B19: =MDETERM(P18:AB30) -> -4.6727017e-93 | P19: =B4-eigen!$B$17*eigen!P4 -> 0.086772465 | Q19: =C4-eigen!$B$17*eigen!Q4 -> 1 | R19: =D4-eigen!$B$17*eigen!R4 -> 0.087659069 | S19: =E4-eigen!$B$17*eigen!S4 -> -0.076947304 | T19: =F4-eigen!$B$17*eigen!T4 -> -0.059238845 | U19: =G4-eigen!$B$17*eigen!U4 -> -0.030776704 | V19: =H4-eigen!$B$17*eigen!V4 -> -0.015172951 | W19: =I4-eigen!$B$17*eigen!W4 -> 0.022769146 | ... AB19: =N4-eigen!$B$17*eigen!AB4 -> 0.10060171
P20: =B5-eigen!$B$17*eigen!P5 -> 0.10415228 | Q20: =C5-eigen!$B$17*eigen!Q5 -> 0.087659069 | R20: =D5-eigen!$B$17*eigen!R5 -> 1 | S20: =E5-eigen!$B$17*eigen!S5 -> -0.15686805 | T20: =F5-eigen!$B$17*eigen!T5 -> 0.17283514 | U20: =G5-eigen!$B$17*eigen!U5 -> 0.40817009 | V20: =H5-eigen!$B$17*eigen!V5 -> 0.48920373 | W20: =I5-eigen!$B$17*eigen!W5 -> 0.69577012 | ... AB20: =N5-eigen!$B$17*eigen!AB5 -> 0.74627704
A21: eigen1 | B21: 7.1032211 | P21: =B6-eigen!$B$17*eigen!P6 -> 0.053015152 | Q21: =C6-eigen!$B$17*eigen!Q6 -> -0.076947304 | R21: =D6-eigen!$B$17*eigen!R6 -> -0.15686805 | S21: =E6-eigen!$B$17*eigen!S6 -> 1 | T21: =F6-eigen!$B$17*eigen!T6 -> 0.89201977 | U21: =G6-eigen!$B$17*eigen!U6 -> 0.77495703 | V21: =H6-eigen!$B$17*eigen!V6 -> 0.71224645 | W21: =I6-eigen!$B$17*eigen!W6 -> -0.025733636 | ... AB21: =N6-eigen!$B$17*eigen!AB6 -> -0.14766876
A22: eigen2 | B22: 3.0191157 | P22: =B7-eigen!$B$17*eigen!P7 -> 0.089529422 | Q22: =C7-eigen!$B$17*eigen!Q7 -> -0.059238845 | R22: =D7-eigen!$B$17*eigen!R7 -> 0.17283514 | S22: =E7-eigen!$B$17*eigen!S7 -> 0.89201977 | T22: =F7-eigen!$B$17*eigen!T7 -> 1 | U22: =G7-eigen!$B$17*eigen!U7 -> 0.96401846 | V22: =H7-eigen!$B$17*eigen!V7 -> 0.92942105 | W22: =I7-eigen!$B$17*eigen!W7 -> 0.42889179 | ... AB22: =N7-eigen!$B$17*eigen!AB7 -> 0.12993878
A23: eigen3 | B23: 1.0696126 | P23: =B8-eigen!$B$17*eigen!P8 -> 0.11712576 | Q23: =C8-eigen!$B$17*eigen!Q8 -> -0.030776704 | R23: =D8-eigen!$B$17*eigen!R8 -> 0.40817009 | S23: =E8-eigen!$B$17*eigen!S8 -> 0.77495703 | T23: =F8-eigen!$B$17*eigen!T8 -> 0.96401846 | U23: =G8-eigen!$B$17*eigen!U8 -> 1 | V23: =H8-eigen!$B$17*eigen!V8 -> 0.9914411 | W23: =I8-eigen!$B$17*eigen!W8 -> 0.58327287 | ... AB23: =N8-eigen!$B$17*eigen!AB8 -> 0.33223412
A24: eigen4 | B24: 0.89855437 | P24: =B9-eigen!$B$17*eigen!P9 -> 0.12970701 | Q24: =C9-eigen!$B$17*eigen!Q9 -> -0.015172951 | R24: =D9-eigen!$B$17*eigen!R9 -> 0.48920373 | S24: =E9-eigen!$B$17*eigen!S9 -> 0.71224645 | T24: =F9-eigen!$B$17*eigen!T9 -> 0.92942105 | U24: =G9-eigen!$B$17*eigen!U9 -> 0.9914411 | V24: =H9-eigen!$B$17*eigen!V9 -> 1 | W24: =I9-eigen!$B$17*eigen!W9 -> 0.63208744 | ... AB24: =N9-eigen!$B$17*eigen!AB9 -> 0.45252938
A25: eigen5 | B25: 0.55112285 | P25: =B10-eigen!$B$17*eigen!P10 -> 0.092054328 | Q25: =C10-eigen!$B$17*eigen!Q10 -> 0.022769146 | R25: =D10-eigen!$B$17*eigen!R10 -> 0.69577012 | S25: =E10-eigen!$B$17*eigen!S10 -> -0.025733636 | T25: =F10-eigen!$B$17*eigen!T10 -> 0.42889179 | U25: =G10-eigen!$B$17*eigen!U10 -> 0.58327287 | V25: =H10-eigen!$B$17*eigen!V10 -> 0.63208744 | W25: =I10-eigen!$B$17*eigen!W10 -> 1 | ... AB25: =N10-eigen!$B$17*eigen!AB10 -> 0.58251174
A26: eigen6 | B26: 0.27080136 | P26: =B11-eigen!$B$17*eigen!P11 -> 0.1160077 | Q26: =C11-eigen!$B$17*eigen!Q11 -> 0.051288644 | R26: =D11-eigen!$B$17*eigen!R11 -> 0.84756561 | S26: =E11-eigen!$B$17*eigen!S11 -> -0.074889631 | T26: =F11-eigen!$B$17*eigen!T11 -> 0.36352858 | U26: =G11-eigen!$B$17*eigen!U11 -> 0.57220287 | V26: =H11-eigen!$B$17*eigen!V11 -> 0.64007297 | W26: =I11-eigen!$B$17*eigen!W11 -> 0.95368059 | ... AB26: =N11-eigen!$B$17*eigen!AB11 -> 0.71581665
A27: eigen7 | B27: 0.087571995 | P27: =B12-eigen!$B$17*eigen!P12 -> 0.12551665 | Q27: =C12-eigen!$B$17*eigen!Q12 -> 0.063348603 | R27: =D12-eigen!$B$17*eigen!R12 -> 0.86696666 | S27: =E12-eigen!$B$17*eigen!S12 -> -0.092651106 | T27: =F12-eigen!$B$17*eigen!T12 -> 0.33451519 | U27: =G12-eigen!$B$17*eigen!U12 -> 0.55161007 | V27: =H12-eigen!$B$17*eigen!V12 -> 0.6329198 | W27: =I12-eigen!$B$17*eigen!W12 -> 0.92501035 | ... AB27: =N12-eigen!$B$17*eigen!AB12 -> 0.80479682
A28: eigen8 | B28: 0 | P28: =B13-eigen!$B$17*eigen!P13 -> 0.1314098 | Q28: =C13-eigen!$B$17*eigen!Q13 -> 0.085298238 | R28: =D13-eigen!$B$17*eigen!R13 -> 0.92488306 | S28: =E13-eigen!$B$17*eigen!S13 -> -0.13594677 | T28: =F13-eigen!$B$17*eigen!T13 -> 0.19875917 | U28: =G13-eigen!$B$17*eigen!U13 -> 0.45213895 | V28: =H13-eigen!$B$17*eigen!V13 -> 0.53666854 | W28: =I13-eigen!$B$17*eigen!W13 -> 0.71129255 | ... AB28: =N13-eigen!$B$17*eigen!AB13 -> 0.78886039
A29: eigen9 | B29: 0 | P29: =B14-eigen!$B$17*eigen!P14 -> 0.14030105 | Q29: =C14-eigen!$B$17*eigen!Q14 -> 0.095362441 | R29: =D14-eigen!$B$17*eigen!R14 -> 0.9069727 | S29: =E14-eigen!$B$17*eigen!S14 -> -0.14731593 | T29: =F14-eigen!$B$17*eigen!T14 -> 0.18368752 | U29: =G14-eigen!$B$17*eigen!U14 -> 0.43136648 | V29: =H14-eigen!$B$17*eigen!V14 -> 0.53346507 | W29: =I14-eigen!$B$17*eigen!W14 -> 0.70068128 | ... AB29: =N14-eigen!$B$17*eigen!AB14 -> 0.90760238
A30: eigen10 | B30: 0 | P30: =B15-eigen!$B$17*eigen!P15 -> 0.13704917 | Q30: =C15-eigen!$B$17*eigen!Q15 -> 0.10060171 | R30: =D15-eigen!$B$17*eigen!R15 -> 0.74627704 | S30: =E15-eigen!$B$17*eigen!S15 -> -0.14766876 | T30: =F15-eigen!$B$17*eigen!T15 -> 0.12993878 | U30: =G15-eigen!$B$17*eigen!U15 -> 0.33223412 | V30: =H15-eigen!$B$17*eigen!V15 -> 0.45252938 | W30: =I15-eigen!$B$17*eigen!W15 -> 0.58251174 | ... AB30: =N15-eigen!$B$17*eigen!AB15 -> 1
A31: eigen11 | B31: 0
A32: eigen12 | B32: 0
A33: eigen13 | B33: 0

Sheet pca
A1: objID | B1: ra | C1: dec | D1: z | E1: u-g | F1: u-r | G1: u-i | H1: u-z | I1: g-r | J1: g-i | K1: g-z | L1: r-i | M1: r-z | N1: i-z | P1: Principal Component Analysis (PCA)
A2: 1.2376623e+18 | B2: 235.65648 | C2: 35.854315 | D2: 0.000108371 | E2: 2.04503 | F2: 3.40004 | G2: 4.06155 | H2: 4.43856 | I2: 1.35501 | J2: 2.01652 | K2: 2.39353 | L2: 0.66151 | M2: 1.03852 | N2: 0.37701 | Q2: PC(1) | R2: PC(2) | S2: PC(3) | T2: PC(4) | U2: PC(5) | V2: PC(6) | W2: PC(7) | X2: PC(8) | Y2: PC(9) | Z2: PC(10) | AA2: PC(11) | AB2: PC(12) | AC2: PC(13)
A3: 1.2376625e+18 | B3: 236.2748 | C3: 35.890829 | D3: 0.006308075 | E3: 0.72406 | F3: 0.86827 | G3: 0.81862 | H3: 0.8866 | I3: 0.14421 | J3: 0.09456 | K3: 0.16254 | L3: -0.04965 | M3: 0.01833 | N3: 0.06798 | P3: Variance | Q3: =_xll.PCA_COMP(_xll.RMNA(pca!$B$2:$N$475,),,1,1,2) -> 7.1032211 | R3: =_xll.PCA_COMP(_xll.RMNA(pca!$B$2:$N$475,),,1,2,2) -> 3.0191157 | S3: =_xll.PCA_COMP(_xll.RMNA(pca!$B$2:$N$475,),,1,3,2) -> 1.0696126 | T3: =_xll.PCA_COMP(_xll.RMNA(pca!$B$2:$N$475,),,1,4,2) -> 0.89855437 | U3: =_xll.PCA_COMP(_xll.RMNA(pca!$B$2:$N$475,),,1,5,2) -> 0.55112285 | V3: =_xll.PCA_COMP(_xll.RMNA(pca!$B$2:$N$475,),,1,6,2) -> 0.27080136 | W3: =_xll.PCA_COMP(_xll.RMNA(pca!$B$2:$N$475,),,1,7,2) -> 0.087571995 | X3: =_xll.PCA_COMP(_xll.RMNA(pca!$B$2:$N$475,),,1,8,2) -> 0 | Y3: =_xll.PCA_COMP(_xll.RMNA(pca!$B$2:$N$475,),,1,9,2) -> 0 | Z3: =_xll.PCA_COMP(_xll.RMNA(pca!$B$2:$N$475,),,1,10,2) -> 0 | AA3: =_xll.PCA_COMP(_xll.RMNA(pca!$B$2:$N$475,),,1,11,2) -> 0 | AB3: =_xll.PCA_COMP(_xll.RMNA(pca!$B$2:$N$475,),,1,12,2) -> 0 | AC3: =_xll.PCA_COMP(_xll.RMNA(pca!$B$2:$N$475,),,1,13,2) -> 0 | AF3: =Q3*10% -> 0.71032211 | AG3: =R3*10% -> 0.30191157 | AH3: =S3*10% -> 0.10696126 | AI3: =T3*10% -> 0.089855437 | AJ3: =U3*10% -> 0.055112285 | AK3: =V3*10% -> 0.027080136 | AL3: =W3*10% -> 0.0087571995 | AM3: =X3*10% -> 0 | ... AQ3: =AB3*10% -> 0 | AR3: 0
A4: 1.2376625e+18 | B4: 236.21743 | C4: 36.479334 | D4: 0.01116591 | E4: 1.11507 | F4: 1.5368 | G4: 1.69315 | H4: 1.81019 | I4: 0.42173 | J4: 0.57808 | K4: 0.69512 | L4: 0.15635 | M4: 0.27339 | N4: 0.11704 | P4: Proportion | Q4: =_xll.PCA_COMP(_xll.RMNA(pca!$B$2:$N$475,),,1,1,1) -> 0.54640162 | R4: =_xll.PCA_COMP(_xll.RMNA(pca!$B$2:$N$475,),,1,2,1) -> 0.23223967 | S4: =_xll.PCA_COMP(_xll.RMNA(pca!$B$2:$N$475,),,1,3,1) -> 0.082277893 | T4: =_xll.PCA_COMP(_xll.RMNA(pca!$B$2:$N$475,),,1,4,1) -> 0.069119567 | U4: =_xll.PCA_COMP(_xll.RMNA(pca!$B$2:$N$475,),,1,5,1) -> 0.042394065 | V4: =_xll.PCA_COMP(_xll.RMNA(pca!$B$2:$N$475,),,1,6,1) -> 0.020830874 | W4: =_xll.PCA_COMP(_xll.RMNA(pca!$B$2:$N$475,),,1,7,1) -> 0.0067363073 | X4: =_xll.PCA_COMP(_xll.RMNA(pca!$B$2:$N$475,),,1,8,1) -> 0 | Y4: =_xll.PCA_COMP(_xll.RMNA(pca!$B$2:$N$475,),,1,9,1) -> 0 | Z4: =_xll.PCA_COMP(_xll.RMNA(pca!$B$2:$N$475,),,1,10,1) -> 0 | AA4: =_xll.PCA_COMP(_xll.RMNA(pca!$B$2:$N$475,),,1,11,1) -> 0 | AB4: =_xll.PCA_COMP(_xll.RMNA(pca!$B$2:$N$475,),,1,12,1) -> 0 | AC4: =_xll.PCA_COMP(_xll.RMNA(pca!$B$2:$N$475,),,1,13,1) -> 0
A5: 1.2376625e+18 | B5: 236.4412 | C5: 36.028097 | D5: 0.01141854 | E5: 1.0158 | F5: 1.36323 | G5: 1.57702 | H5: 1.6244 | I5: 0.34743 | J5: 0.56122 | K5: 0.6086 | L5: 0.21379 | M5: 0.26117 | N5: 0.04738 | P5: Cum. Proportion | Q5: =$Q$4 -> 0.54640162 | R5: =$R$4+$Q$5 -> 0.77864129 | S5: =$S$4+$R$5 -> 0.86091919 | T5: =$T$4+$S$5 -> 0.93003875 | U5: =$U$4+$T$5 -> 0.97243282 | V5: =$V$4+$U$5 -> 0.99326369 | W5: =$W$4+$V$5 -> 1 | X5: =$X$4+$W$5 -> 1 | Y5: =$Y$4+$X$5 -> 1 | Z5: =$Z$4+$Y$5 -> 1 | AA5: =$AA$4+$Z$5 -> 1 | AB5: =$AB$4+$AA$5 -> 1 | AC5: =$AC$4+$AB$5 -> 1
A6: 1.2376625e+18 | B6: 236.2044 | C6: 36.563143 | D6: 0.03872261 | E6: 1.32078 | F6: 1.82759 | G6: 2.0776 | H6: 2.21528 | I6: 0.50681 | J6: 0.75682 | K6: 0.8945 | L6: 0.25001 | M6: 0.38769 | N6: 0.13768
A7: 1.2376623e+18 | B7: 235.95322 | C7: 35.634052 | D7: 0.04851187 | E7: 1.10182 | F7: 1.51008 | G7: 1.77106 | H7: 1.9507 | I7: 0.40826 | J7: 0.66924 | K7: 0.84888 | L7: 0.26098 | M7: 0.44062 | N7: 0.17964 | P7: Loadings | Q7: PC(1) | R7: PC(2) | S7: PC(3) | T7: PC(4) | U7: PC(5) | V7: PC(6) | W7: PC(7) | X7: PC(8) | Y7: PC(9) | Z7: PC(10) | AA7: PC(11) | AB7: PC(12) | AC7: PC(13)
A8: 1.2376615e+18 | B8: 236.42283 | C8: 35.660888 | D8: 0.05498169 | E8: 1.50337 | F8: 2.0518 | G8: 2.31401 | H8: 2.53843 | I8: 0.54843 | J8: 0.81064 | K8: 1.03506 | L8: 0.26221 | M8: 0.48663 | N8: 0.22442 | P8: ra | Q8: {=_xll.PCA_COMP(_xll.RMNA(pca!$B$2:$N$475,),,1,1,4)} -> -0.061806993 | R8: {=_xll.PCA_COMP(_xll.RMNA(pca!$B$2:$N$475,),,1,2,4)} -> -0.014684222 | S8: {=_xll.PCA_COMP(_xll.RMNA(pca!$B$2:$N$475,),,1,3,4)} -> 0.68885637 | T8: {=_xll.PCA_COMP(_xll.RMNA(pca!$B$2:$N$475,),,1,4,4)} -> -0.71486296 | U8: {=_xll.PCA_COMP(_xll.RMNA(pca!$B$2:$N$475,),,1,5,4)} -> -0.09803776 | V8: {=_xll.PCA_COMP(_xll.RMNA(pca!$B$2:$N$475,),,1,6,4)} -> 0.023767071 | W8: {=_xll.PCA_COMP(_xll.RMNA(pca!$B$2:$N$475,),,1,7,4)} -> -0.015357411 | X8: {=_xll.PCA_COMP(_xll.RMNA(pca!$B$2:$N$475,),,1,8,4)} -> -8.3090283e-16 | Y8: {=_xll.PCA_COMP(_xll.RMNA(pca!$B$2:$N$475,),,1,9,4)} -> 5.7729239e-16 | Z8: {=_xll.PCA_COMP(_xll.RMNA(pca!$B$2:$N$475,),,1,10,4)} -> 2.3332946e-16 | AA8: {=_xll.PCA_COMP(_xll.RMNA(pca!$B$2:$N$475,),,1,11,4)} -> 2.0016595e-17 | AB8: {=_xll.PCA_COMP(_xll.RMNA(pca!$B$2:$N$475,),,1,12,4)} -> 2.5452903e-17 | AC8: {=_xll.PCA_COMP(_xll.RMNA(pca!$B$2:$N$475,),,1,13,4)} -> -2.0192082e-17
A9: 1.2376615e+18 | B9: 236.4388 | C9: 35.659931 | D9: 0.0551876 | E9: 1.99307 | F9: 2.90228 | G9: 3.34674 | H9: 3.68612 | I9: 0.90921 | J9: 1.35367 | K9: 1.69305 | L9: 0.44446 | M9: 0.78384 | N9: 0.33938 | P9: dec | Q9: -0.023726159 | R9: 0.084863243 | S9: 0.70771656 | T9: 0.69483278 | U9: -0.092456674 | V9: -0.0001215583 | W9: 0.0056317205 | X9: 1.6712932e-16 | Y9: -1.436917e-15 | Z9: -5.0587257e-17 | AA9: -2.5570929e-17 | AB9: 4.5965346e-17 | AC9: 4.147635e-17
A10: 1.2376615e+18 | B10: 236.4388 | C10: 35.659931 | D10: 0.05523921 | E10: 1.99307 | F10: 2.90228 | G10: 3.34674 | H10: 3.68612 | I10: 0.90921 | J10: 1.35367 | K10: 1.69305 | L10: 0.44446 | M10: 0.78384 | N10: 0.33938 | P10: z | Q10: -0.3243265 | R10: 0.18886036 | S10: -0.021542626 | T10: 0.015276024 | U10: 0.16180131 | V10: 0.55835958 | W10: -0.72145794 | X10: -1.0052581e-14 | Y10: -4.1356795e-15 | Z10: 1.1352229e-14 | AA10: 4.4910622e-17 | AB10: -1.9474143e-17 | AC10: 5.040624e-17
A11: 1.2376625e+18 | B11: 236.28331 | C11: 36.184873 | D11: 0.05844347 | E11: 1.33689 | F11: 1.95728 | G11: 2.29236 | H11: 2.49538 | I11: 0.62039 | J11: 0.95547 | K11: 1.15849 | L11: 0.33508 | M11: 0.5381 | N11: 0.20302 | P11: u-g | Q11: -0.056111628 | R11: -0.55727488 | S11: 0.057874455 | T11: 0.040414084 | U11: 0.24833722 | V11: 0.05954526 | W11: -0.019750414 | X11: 0.05822674 | Y11: 0.013188329 | Z11: -0.63278283 | AA11: 0.38297255 | AB11: -0.15792825 | AC11: -0.20029641
A12: 1.2376625e+18 | B12: 236.24143 | C12: 36.06883 | D12: 0.0599989 | E12: 1.88341 | F12: 2.76878 | G12: 3.18127 | H12: 3.52614 | I12: 0.88537 | J12: 1.29786 | K12: 1.64273 | L12: 0.41249 | M12: 0.75736 | N12: 0.34487 | P12: u-r | Q12: -0.19825773 | R12: -0.48709231 | S12: 0.0054000348 | T12: 0.04040157 | U12: -0.056441586 | V12: -0.046388486 | W12: -0.086249139 | X12: 0.059894194 | Y12: -0.25494901 | Z12: 0.57300464 | AA12: 0.44578272 | AB12: 0.3012079 | AC12: 0.15042601
A13: 1.2376625e+18 | B13: 236.261 | C13: 36.156339 | D13: 0.06039927 | E13: 1.95959 | F13: 2.84952 | G13: 3.27597 | H13: 3.6085 | I13: 0.88993 | J13: 1.31638 | K13: 1.64891 | L13: 0.42645 | M13: 0.75898 | N13: 0.33253 | P13: u-i | Q13: -0.27248963 | R13: -0.39458804 | S13: 0.0032142516 | T13: 0.035207632 | U13: 0.00093450177 | V13: 0.060446774 | W13: 0.066842978 | X13: -0.36153173 | Y13: 0.70266893 | Z13: 0.1413117 | AA13: -0.29193534 | AB13: -0.048333386 | AC13: 0.16940167
A14: 1.2376625e+18 | B14: 236.22997 | C14: 36.067765 | D14: 0.0610057 | E14: 1.89412 | F14: 2.80548 | G14: 3.22707 | H14: 3.56626 | I14: 0.91136 | J14: 1.33295 | K14: 1.67214 | L14: 0.42159 | M14: 0.76078 | N14: 0.33919 | P14: u-z | Q14: -0.29868439 | R14: -0.34643768 | S14: 0.0096385666 | T14: 0.031050777 | U14: 0.067668101 | V14: -0.037739999 | W14: 0.029919843 | X14: 0.23789882 | Y14: -0.46387618 | Z14: -0.001586431 | AA14: -0.70182507 | AB14: -0.095824384 | AC14: -0.096399296
A15: 1.2376625e+18 | B15: 236.22997 | C15: 36.067765 | D15: 0.06104444 | E15: 1.89412 | F15: 2.80548 | G15: 3.22707 | H15: 3.56626 | I15: 0.91136 | J15: 1.33295 | K15: 1.67214 | L15: 0.42159 | M15: 0.76078 | N15: 0.33919 | P15: g-r | Q15: -0.32633736 | R15: 0.036474917 | S15: -0.10372424 | T15: 0.0085838958 | U15: -0.62115493 | V15: -0.22160284 | W15: -0.15128202 | X15: 0.16958118 | Y15: 0.14688494 | Z15: 0.069041837 | AA15: 0.13923712 | AB15: -0.36295543 | AC15: -0.466144
A16: 1.2376625e+18 | B16: 236.38213 | C16: 36.217623 | D16: 0.06134604 | E16: 1.86636 | F16: 2.72941 | G16: 3.14202 | H16: 3.46 | I16: 0.86305 | J16: 1.27566 | K16: 1.59364 | L16: 0.41261 | M16: 0.73059 | N16: 0.31798 | P16: g-i | Q16: -0.35712285 | R16: 0.10054827 | S16: -0.070027438 | T16: 0.0031086073 | U16: -0.32077219 | V16: 0.018105995 | W16: 0.13109335 | X16: -0.49789252 | Y16: -0.37409798 | Z16: -0.28472668 | AA16: 0.11241327 | AB16: -0.17125866 | AC16: 0.47555222
A17: 1.2376625e+18 | B17: 236.42131 | C17: 36.137426 | D17: 0.06137229 | E17: 0.98523 | F17: 1.30908 | G17: 1.59258 | H17: 1.69677 | I17: 0.32385 | J17: 0.60735 | K17: 0.71154 | L17: 0.2835 | M17: 0.38769 | N17: 0.10419 | P17: g-z | Q17: -0.36179852 | R17: 0.12323797 | S17: -0.050162162 | T17: -0.00053006703 | U17: -0.17792379 | V17: -0.11921232 | W17: 0.064226197 | X17: 0.33126232 | Y17: 0.18591501 | Z17: -0.36383374 | AA17: -0.037330423 | AB17: 0.71596593 | AC17: 0.10358264
A18: 1.2376625e+18 | B18: 236.16559 | C18: 36.137926 | D18: 0.06155551 | E18: 1.83447 | F18: 2.63866 | G18: 2.99538 | H18: 3.26296 | I18: 0.80419 | J18: 1.16091 | K18: 1.42849 | L18: 0.35672 | M18: 0.6243 | N18: 0.26758 | P18: r-i | Q18: -0.33937379 | R18: 0.17960525 | S18: -0.0062686398 | T18: -0.0057588208 | U18: 0.19282161 | V18: 0.37849323 | W18: 0.53581696 | X18: 0.44627565 | Y18: 0.10228472 | Z18: 0.14696279 | AA18: 0.18106728 | AB18: -0.31132567 | AC18: 0.15500512
A19: 1.2376625e+18 | B19: 236.38393 | C19: 36.077117 | D19: 0.06209526 | E19: 1.0198 | F19: 1.38881 | G19: 1.65753 | H19: 1.78982 | I19: 0.36901 | J19: 0.63773 | K19: 0.77002 | L19: 0.26872 | M19: 0.40101 | N19: 0.13229 | P19: r-z | Q19: -0.34120391 | R19: 0.19362179 | S19: 0.013297602 | T19: -0.0098913131 | U19: 0.30961989 | V19: 0.0057952392 | W19: 0.27738847 | X19: -0.46351984 | Y19: -0.11922827 | Z19: 0.10148195 | AA19: 0.063785741 | AB19: 0.23692485 | AC19: -0.61107021
A20: 1.2376625e+18 | B20: 236.19078 | C20: 36.079215 | D20: 0.06218404 | E20: 1.78613 | F20: 2.62508 | G20: 3.04295 | H20: 3.33189 | I20: 0.83895 | J20: 1.25682 | K20: 1.54576 | L20: 0.41787 | M20: 0.70681 | N20: 0.28894 | P20: i-z | Q20: -0.2966244 | R20: 0.19236933 | S20: 0.047679311 | T20: -0.016157132 | U20: 0.48248736 | V20: -0.68553345 | W20: -0.24041172 | X20: 0.072933049 | Y20: 0.071665329 | Z20: 0.034239824 | AA20: 0.080955927 | AB20: -0.21467089 | AC20: 0.21831335
A21: 1.2376625e+18 | B21: 236.18645 | C21: 36.129856 | D21: 0.06279468 | E21: 1.97194 | F21: 2.87787 | G21: 3.30577 | H21: 3.64975 | I21: 0.90593 | J21: 1.33383 | K21: 1.67781 | L21: 0.4279 | M21: 0.77188 | N21: 0.34398
A22: 1.2376625e+18 | B22: 236.09999 | C22: 36.135241 | D22: 0.06282794 | E22: 1.73946 | F22: 2.53892 | G22: 2.92469 | H22: 3.15415 | I22: 0.79946 | J22: 1.18523 | K22: 1.41469 | L22: 0.38577 | M22: 0.61523 | N22: 0.22946 | P22: Values | Q22: PC(1) | R22: PC(2) | S22: PC(3) | T22: PC(4) | U22: PC(5) | V22: PC(6) | W22: PC(7) | X22: PC(8) | Y22: PC(9) | Z22: PC(10) | AA22: PC(11) | AB22: PC(12) | AC22: PC(13)
A23: 1.2376625e+18 | B23: 236.2503 | C23: 36.110351 | D23: 0.06285614 | E23: 1.86984 | F23: 2.79216 | G23: 3.22688 | H23: 3.6159 | I23: 0.92232 | J23: 1.35704 | K23: 1.74606 | L23: 0.43472 | M23: 0.82374 | N23: 0.38902 | Q23: {=_xll.PCA_COMP(_xll.RMNA(pca!$B$2:$N$475,),,1,1,5)} -> 0.62097452 | R23: {=_xll.PCA_COMP(_xll.RMNA(pca!$B$2:$N$475,),,1,2,5)} -> -0.76512384 | S23: {=_xll.PCA_COMP(_xll.RMNA(pca!$B$2:$N$475,),,1,3,5)} -> -1.8421704 | T23: {=_xll.PCA_COMP(_xll.RMNA(pca!$B$2:$N$475,),,1,4,5)} -> 0.78335112 | U23: {=_xll.PCA_COMP(_xll.RMNA(pca!$B$2:$N$475,),,1,5,5)} -> -0.083771225 | V23: {=_xll.PCA_COMP(_xll.RMNA(pca!$B$2:$N$475,),,1,6,5)} -> -0.70822803 | W23: {=_xll.PCA_COMP(_xll.RMNA(pca!$B$2:$N$475,),,1,7,5)} -> 0.89288705 | X23: {=_xll.PCA_COMP(_xll.RMNA(pca!$B$2:$N$475,),,1,8,5)} -> 0 | Y23: {=_xll.PCA_COMP(_xll.RMNA(pca!$B$2:$N$475,),,1,9,5)} -> 0 | Z23: {=_xll.PCA_COMP(_xll.RMNA(pca!$B$2:$N$475,),,1,10,5)} -> 0 | AA23: {=_xll.PCA_COMP(_xll.RMNA(pca!$B$2:$N$475,),,1,11,5)} -> 0 | AB23: {=_xll.PCA_COMP(_xll.RMNA(pca!$B$2:$N$475,),,1,12,5)} -> 0 | AC23: {=_xll.PCA_COMP(_xll.RMNA(pca!$B$2:$N$475,),,1,13,5)} -> 0
A24: 1.2376625e+18 | B24: 236.19515 | C24: 35.950268 | D24: 0.06286892 | E24: 2.01011 | F24: 2.89555 | G24: 3.31256 | H24: 3.61431 | I24: 0.88544 | J24: 1.30245 | K24: 1.6042 | L24: 0.41701 | M24: 0.71876 | N24: 0.30175 | Q24: 7.0133944 | R24: 1.2791033 | S24: -0.11628536 | T24: -0.77485536 | U24: 0.16003973 | V24: 0.45093517 | W24: -0.61208183 | X24: 0 | Y24: 0 | Z24: 0 | AA24: 0 | AB24: 0 | AC24: 0
A25: 1.2376625e+18 | B25: 236.24133 | C25: 36.188203 | D25: 0.06332173 | E25: 1.82233 | F25: 2.66788 | G25: 3.06453 | H25: 3.354 | I25: 0.84555 | J25: 1.2422 | K25: 1.53167 | L25: 0.39665 | M25: 0.68612 | N25: 0.28947 | Q25: 5.3488902 | R25: 0.84979636 | S25: 1.1591594 | T25: 0.88063004 | U25: -0.13166175 | V25: 0.33944754 | W25: -0.15733508 | X25: 0 | Y25: 0 | Z25: 0 | AA25: 0 | AB25: 0 | AC25: 0
A26: 1.2376625e+18 | B26: 236.23274 | C26: 36.138508 | D26: 0.06371365 | E26: 1.92347 | F26: 2.77902 | G26: 3.16442 | H26: 3.46772 | I26: 0.85555 | J26: 1.24095 | K26: 1.54425 | L26: 0.3854 | M26: 0.6887 | N26: 0.3033 | Q26: 5.6023263 | R26: 0.85312964 | S26: 0.49564519 | T26: -0.7368677 | U26: -0.12265461 | V26: 0.73000457 | W26: 0.018082531 | X26: 0 | Y26: 0 | Z26: 0 | AA26: 0 | AB26: 0 | AC26: 0
A27: 1.2376625e+18 | B27: 236.64889 | C27: 36.16354 | D27: 0.06372982 | E27: 1.01871 | F27: 1.45528 | G27: 1.77727 | H27: 1.97137 | I27: 0.43657 | J27: 0.75856 | K27: 0.95266 | L27: 0.32199 | M27: 0.51609 | N27: 0.1941 | Q27: 4.6458071 | R27: 0.5996452 | S27: 1.3190431 | T27: 1.1528664 | U27: -0.11532006 | V27: 0.37608269 | W27: -0.023513633 | X27: 0 | Y27: 0 | Z27: 0 | AA27: 0 | AB27: 0 | AC27: 0
A28: 1.2376625e+18 | B28: 236.09188 | C28: 36.105321 | D28: 0.06383671 | E28: 1.89928 | F28: 2.81325 | G28: 3.23922 | H28: 3.57214 | I28: 0.91397 | J28: 1.33994 | K28: 1.67286 | L28: 0.42597 | M28: 0.75889 | N28: 0.33292 | Q28: 4.9600853 | R28: 0.81208754 | S28: -1.5188748 | T28: -0.6234279 | U28: 0.53671271 | V28: 0.27312641 | W28: -0.048708121 | X28: 0 | Y28: 0 | Z28: 0 | AA28: 0 | AB28: 0 | AC28: 0
A29: 1.2376625e+18 | B29: 236.44992 | C29: 35.928752 | D29: 0.06386434 | E29: 1.60395 | F29: 2.44741 | G29: 2.8331 | H29: 3.13723 | I29: 0.84346 | J29: 1.22915 | K29: 1.53328 | L29: 0.38569 | M29: 0.68982 | N29: 0.30413 | Q29: 4.1532791 | R29: 0.13832046 | S29: -0.46289065 | T29: -1.5281194 | U29: 0.37605424 | V29: 0.0824253 | W29: -0.13186103 | X29: 0 | Y29: 0 | Z29: 0 | AA29: 0 | AB29: 0 | AC29: 0
A30: 1.2376625e+18 | B30: 235.8664 | C30: 36.370778 | D30: 0.06389388 | E30: 2.00953 | F30: 2.92309 | G30: 3.36833 | H30: 3.67713 | I30: 0.91356 | J30: 1.3588 | K30: 1.6676 | L30: 0.44524 | M30: 0.75404 | N30: 0.3088 | Q30: 2.1630148 | R30: -0.61369314 | S30: -0.51144385 | T30: -1.470295 | U30: 0.31758304 | V30: -0.36172231 | W30: 0.21069116 | X30: 0 | Y30: 0 | Z30: 0 | AA30: 0 | AB30: 0 | AC30: 0
A31: 1.2376625e+18 | B31: 236.17264 | C31: 36.06545 | D31: 0.06399604 | E31: 1.82036 | F31: 2.70346 | G31: 3.12178 | H31: 3.42206 | I31: 0.8831 | J31: 1.30142 | K31: 1.6017 | L31: 0.41832 | M31: 0.7186 | N31: 0.30028 | Q31: 2.1629492 | R31: -0.61365492 | S31: -0.51144821 | T31: -1.4702919 | U31: 0.31761579 | V31: -0.36160932 | W31: 0.21054516 | X31: 0 | Y31: 0 | Z31: 0 | AA31: 0 | AB31: 0 | AC31: 0
A32: 1.2376625e+18 | B32: 236.24023 | C32: 36.020008 | D32: 0.06411387 | E32: 1.8021 | F32: 2.66513 | G32: 3.06724 | H32: 3.36483 | I32: 0.86303 | J32: 1.26514 | K32: 1.56273 | L32: 0.40211 | M32: 0.6997 | N32: 0.29759 | Q32: 3.9363919 | R32: 0.5325215 | S32: 0.50461928 | T32: 0.059184726 | U32: 0.056508466 | V32: 0.1940615 | W32: 0.069470808 | X32: 0 | Y32: 0 | Z32: 0 | AA32: 0 | AB32: 0 | AC32: 0
A33: 1.2376615e+18 | B33: 236.06752 | C33: 35.897172 | D33: 0.06413121 | E33: 1.82611 | F33: 2.6731 | G33: 3.08937 | H33: 3.37383 | I33: 0.84699 | J33: 1.26326 | K33: 1.54772 | L33: 0.41627 | M33: 0.70073 | N33: 0.28446 | Q33: 2.3653092 | R33: -0.30213224 | S33: 0.100344 | T33: -0.046287626 | U33: 0.25900972 | V33: -0.41187942 | W33: 0.1350904 | X33: 0 | Y33: 0 | Z33: 0 | AA33: 0 | AB33: 0 | AC33: 0
A34: 1.2376625e+18 | B34: 236.2393 | C34: 36.117985 | D34: 0.06424987 | E34: 2.24907 | F34: 3.16456 | G34: 3.66222 | H34: 3.95979 | I34: 0.91549 | J34: 1.41315 | K34: 1.71072 | L34: 0.49766 | M34: 0.79523 | N34: 0.29757 | Q34: 2.2866507 | R34: -0.4068743 | S34: 0.36049119 | T34: 0.13770276 | U34: 0.20534711 | V34: -0.34594478 | W34: 0.17597768 | X34: 0 | Y34: 0 | Z34: 0 | AA34: 0 | AB34: 0 | AC34: 0
A35: 1.2376625e+18 | B35: 236.62189 | C35: 35.936266 | D35: 0.0642834 | E35: 1.97654 | F35: 2.90621 | G35: 3.32241 | H35: 3.65194 | I35: 0.92967 | J35: 1.34587 | K35: 1.6754 | L35: 0.4162 | M35: 0.74573 | N35: 0.32953 | Q35: 2.2933588 | R35: -0.33777947 | S35: 0.062844915 | T35: -0.018764771 | U35: 0.2067089 | V35: -0.39277334 | W35: 0.15739149 | X35: 0 | Y35: 0 | Z35: 0 | AA35: 0 | AB35: 0 | AC35: 0
... A475: 1.2376625e+18 | B475: 235.98914 | C475: 36.504567 | D475: 1.530724 | E475: 1.52142 | F475: 2.81548 | G475: 3.82687 | H475: 4.65748 | I475: 1.29406 | J475: 2.30545 | K475: 3.13606 | L475: 1.01139 | M475: 1.842 | N475: 0.83061 | Q475: -4.2367638 | R475: -0.032866049 | S475: 1.2878945 | T475: -0.18038378 | U475: -0.47610551 | V475: 0.39442258 | W475: -0.11873093 | X475: 0 | Y475: 0 | Z475: 0 | AA475: 0 | AB475: 0 | AC475: 0
Q476: -4.2607428 | R476: 2.6560896 | S476: 0.70213431 | T476: -0.62744441 | U476: 0.32154761 | V476: -0.89760678 | W476: -0.24385912 | X476: 0 | Y476: 0 | Z476: 0 | AA476: 0 | AB476: 0 | AC476: 0
Q477: -6.3491686 | R477: -0.091668106 | S477: 1.1350324 | T477: -0.40787405 | U477: 2.1020264 | V477: 0.41870516 | W477: 1.3847631 | X477: 0 | Y477: 0 | Z477: 0 | AA477: 0 | AB477: 0 | AC477: 0
Q478: -3.5598946 | R478: 4.7877647 | S478: 0.71825448 | T478: -0.81120021 | U478: 0.10076067 | V478: -0.082545396 | W478: 0.57135068 | X478: 0 | Y478: 0 | Z478: 0 | AA478: 0 | AB478: 0 | AC478: 0
Q479: -3.5605895 | R479: 4.7881676 | S479: 0.71819073 | T479: -0.81118468 | U479: 0.10110993 | V479: -0.081348021 | W479: 0.56980341 | X479: 0 | Y479: 0 | Z479: 0 | AA479: 0 | AB479: 0 | AC479: 0
...

Sheet 2 pc
A1: objID | B1: ra | C1: dec | D1: z | E1: u-g | F1: u-r | G1: u-i | H1: u-z | I1: g-r | J1: g-i | K1: g-z | L1: r-i | M1: r-z | N1: i-z | O1: PC(1) | P1: PC(2) | Q1: Rproj | R1: Vrad
A2: 1.2376615e+18 | B2: 236.4388 | C2: 35.659931 | D2: 0.0551876 | E2: 1.99307 | F2: 2.90228 | G2: 3.34674 | H2: 3.68612 | I2: 0.90921 | J2: 1.35367 | K2: 1.69305 | L2: 0.44446 | M2: 0.78384 | N2: 0.33938 | O2: 2.1630148 | P2: -0.61369314 | Q2: 2.5682362 | R2: 16556.28
A3: 1.2376615e+18 | B3: 236.4388 | C3: 35.659931 | D3: 0.05523921 | E3: 1.99307 | F3: 2.90228 | G3: 3.34674 | H3: 3.68612 | I3: 0.90921 | J3: 1.35367 | K3: 1.69305 | L3: 0.44446 | M3: 0.78384 | N3: 0.33938 | O3: 2.1629492 | P3: -0.61365492 | Q3: 2.5682362 | R3: 16571.763
A4: 1.2376625e+18 | B4: 236.19515 | C4: 35.950268 | D4: 0.06286892 | E4: 2.01011 | F4: 2.89555 | G4: 3.31256 | H4: 3.61431 | I4: 0.88544 | J4: 1.30245 | K4: 1.6042 | L4: 0.41701 | M4: 0.71876 | N4: 0.30175 | O4: 2.4079914 | P4: -0.58682915 | Q4: 0.88725365 | R4: 18860.676
A5: 1.2376625e+18 | B5: 236.62267 | C5: 35.791443 | D5: 0.07924994 | E5: 1.97549 | F5: 2.91675 | G5: 3.3417 | H5: 3.67074 | I5: 0.94126 | J5: 1.36621 | K5: 1.69525 | L5: 0.42495 | M5: 0.75399 | N5: 0.32904 | O5: 2.1197622 | P5: -0.58463439 | Q5: 2.3776895 | R5: 23774.982
A6: 1.2376625e+18 | B6: 236.62189 | C6: 35.936266 | D6: 0.0642834 | E6: 1.97654 | F6: 2.90621 | G6: 3.32241 | H6: 3.65194 | I6: 0.92967 | J6: 1.34587 | K6: 1.6754 | L6: 0.4162 | M6: 0.74573 | N6: 0.32953 | O6: 2.1754943 | P6: -0.55051894 | Q6: 1.8882414 | R6: 19285.02
A7: 1.2376615e+18 | B7: 236.36339 | C7: 35.81127 | D7: 0.06633139 | E7: 1.95315 | F7: 2.83219 | G7: 3.2435 | H7: 3.5412 | I7: 0.87904 | J7: 1.29035 | K7: 1.58805 | L7: 0.41131 | M7: 0.70901 | N7: 0.2977 | O7: 2.4647736 | P7: -0.54882831 | Q7: 1.6889332 | R7: 19899.417
A8: 1.2376625e+18 | B8: 236.25418 | C8: 36.106436 | D8: 0.06515587 | E8: 2.00281 | F8: 2.88893 | G8: 3.32027 | H8: 3.60517 | I8: 0.88612 | J8: 1.31746 | K8: 1.60236 | L8: 0.43134 | M8: 0.71624 | N8: 0.2849 | O8: 2.3910008 | P8: -0.54351589 | Q8: 0.039299088 | R8: 19546.761
A9: 1.2376625e+18 | B9: 236.35446 | C9: 36.020179 | D9: 0.06644917 | E9: 2.01144 | F9: 2.9163 | G9: 3.33456 | H9: 3.67602 | I9: 0.90486 | J9: 1.32312 | K9: 1.66458 | L9: 0.41826 | M9: 0.75972 | N9: 0.34146 | O9: 2.203858 | P9: -0.53222113 | Q9: 0.67532665 | R9: 19934.751 | AB9: PC1 | AC9: 2.005-3.24
A10: 1.2376615e+18 | B10: 236.30957 | C10: 35.697832 | D10: 0.06927066 | E10: 1.91677 | F10: 2.81832 | G10: 3.24712 | H10: 3.55283 | I10: 0.90155 | J10: 1.33035 | K10: 1.63606 | L10: 0.4288 | M10: 0.73451 | N10: 0.30571 | O10: 2.3815624 | P10: -0.51540147 | Q10: 2.238695 | R10: 20781.198 | AB10: PC2 | AC10: min 0.7-0.12
A11: 1.2376625e+18 | B11: 236.31521 | C11: 36.017164 | D11: 0.06683443 | E11: 1.98556 | F11: 2.88923 | G11: 3.30483 | H11: 3.63357 | I11: 0.90367 | J11: 1.31927 | K11: 1.64801 | L11: 0.4156 | M11: 0.74434 | N11: 0.32874 | O11: 2.2769157 | P11: -0.50818958 | Q11: 0.58247898 | R11: 20050.329 | AB11: PC3 | AC11: 2- min 1.2
A12: 1.2376625e+18 | B12: 236.21942 | C12: 36.215575 | D12: 0.06667417 | E12: 2.00424 | F12: 2.85882 | G12: 3.25289 | H12: 3.54593 | I12: 0.85458 | J12: 1.24865 | K12: 1.54169 | L12: 0.39407 | M12: 0.68711 | N12: 0.29304 | O12: 2.5404439 | P12: -0.50053306 | Q12: 0.58422039 | R12: 20002.251
A13: 1.2376625e+18 | B13: 236.51519 | C13: 35.948939 | D13: 0.06718121 | E13: 1.95251 | F13: 2.84082 | G13: 3.24868 | H13: 3.56514 | I13: 0.88831 | J13: 1.29617 | K13: 1.61263 | L13: 0.40786 | M13: 0.72432 | N13: 0.31646 | O13: 2.3588612 | P13: -0.49618288 | Q13: 1.459716 | R13: 20154.363
A14: 1.2376625e+18 | B14: 236.79683 | C14: 35.660555 | D14: 0.08067437 | E14: 1.90137 | F14: 2.81227 | G14: 3.22926 | H14: 3.56877 | I14: 0.9109 | J14: 1.32789 | K14: 1.6674 | L14: 0.41699 | M14: 0.7565 | N14: 0.33951 | O14: 2.2036051 | P14: -0.48474584 | Q14: 3.4161113 | R14: 24202.311
A15: 1.2376623e+18 | B15: 235.88794 | C15: 35.759865 | D15: 0.06916604 | E15: 1.90902 | F15: 2.77942 | G15: 3.17691 | H15: 3.46706 | I15: 0.8704 | J15: 1.26789 | K15: 1.55804 | L15: 0.39749 | M15: 0.68764 | N15: 0.29015 | O15: 2.6683306 | P15: -0.48401802 | Q15: 2.4508866 | R15: 20749.812
A16: 1.2376625e+18 | B16: 236.73812 | C16: 35.655125 | D16: 0.07957052 | E16: 1.9329 | F16: 2.82483 | G16: 3.25738 | H16: 3.61794 | I16: 0.89193 | J16: 1.32448 | K16: 1.68504 | L16: 0.43255 | M16: 0.79311 | N16: 0.36056 | O16: 2.1261955 | P16: -0.48355281 | Q16: 3.2622504 | R16: 23871.156
A17: 1.2376625e+18 | B17: 236.36477 | C17: 36.013185 | D17: 0.06695418 | E17: 1.98799 | F17: 2.93209 | G17: 3.37174 | H17: 3.7352 | I17: 0.9441 | J17: 1.38375 | K17: 1.74721 | L17: 0.43965 | M17: 0.80311 | N17: 0.36346 | O17: 2.0051699 | P17: -0.48225293 | Q17: 0.73380659 | R17: 20086.254
A18: 1.2376625e+18 | B18: 236.47275 | C18: 35.867583 | D18: 0.06982754 | E18: 1.93505 | F18: 2.82438 | G18: 3.24309 | H18: 3.56436 | I18: 0.88933 | J18: 1.30804 | K18: 1.62931 | L18: 0.41871 | M18: 0.73998 | N18: 0.32127 | O18: 2.3332563 | P18: -0.47709108 | Q18: 1.6383709 | R18: 20948.262
A19: 1.2376625e+18 | B19: 236.80718 | C19: 36.161382 | D19: 0.06819547 | E19: 1.94331 | F19: 2.73895 | G19: 3.09617 | H19: 3.36004 | I19: 0.79564 | J19: 1.15286 | K19: 1.41673 | L19: 0.35722 | M19: 0.62109 | N19: 0.26387 | O19: 2.7948532 | P19: -0.46759061 | Q19: 2.4619321 | R19: 20458.641
A20: 1.2376625e+18 | B20: 236.63885 | C20: 35.784724 | D20: 0.06543288 | E20: 1.8968 | F20: 2.75726 | G20: 3.16206 | H20: 3.47257 | I20: 0.86046 | J20: 1.26526 | K20: 1.57577 | L20: 0.4048 | M20: 0.71531 | N20: 0.31051 | O20: 2.4751516 | P20: -0.45579975 | Q20: 2.4529737 | R20: 19629.864
A21: 1.2376625e+18 | B21: 236.34596 | C21: 36.106418 | D21: 0.06874521 | E21: 1.94298 | F21: 2.84779 | G21: 3.26251 | H21: 3.56614 | I21: 0.90481 | J21: 1.31953 | K21: 1.62316 | L21: 0.41472 | M21: 0.71835 | N21: 0.30363 | O21: 2.3647164 | P21: -0.44922986 | Q21: 0.43620624 | R21: 20623.563
A22: 1.2376625e+18 | B22: 236.43817 | C22: 35.865676 | D22: 0.06603753 | E22: 1.93647 | F22: 2.81787 | G22: 3.24727 | H22: 3.58495 | I22: 0.8814 | J22: 1.3108 | K22: 1.64848 | L22: 0.4294 | M22: 0.76708 | N22: 0.33768 | O22: 2.2798968 | P22: -0.44739253 | Q22: 1.5604547 | R22: 19811.259
A23: 1.2376625e+18 | B23: 236.10839 | C23: 36.062104 | D23: 0.06439563 | E23: 1.93309 | F23: 2.81266 | G23: 3.20545 | H23: 3.50358 | I23: 0.87957 | J23: 1.27236 | K23: 1.57049 | L23: 0.39279 | M23: 0.69092 | N23: 0.29813 | O23: 2.5617073 | P23: -0.44290918 | Q23: 0.65219401 | R23: 19318.689
... A103: 1.2376625e+18 | B103: 236.03367 | C103: 36.556773 | D103: 0.06849528 | E103: 1.75099 | F103: 2.5737 | G103: 2.95536 | H103: 3.26797 | I103: 0.82271 | J103: 1.20437 | K103: 1.51698 | L103: 0.38166 | M103: 0.69427 | N103: 0.31261 | O103: 2.7643371 | P103: 0.049207451 | Q103: 2.5844002 | R103: 20548.584

Sheet 3 pc
A1: objID | B1: ra | C1: dec | D1: z | E1: u-g | F1: u-r | G1: u-i | H1: u-z | I1: g-r | J1: g-i | K1: g-z | L1: r-i | M1: r-z | N1: i-z | O1: PC(1) | P1: PC(2) | Q1: PC(3)
A2: 1.2376623e+18 | B2: 235.65648 | C2: 35.854315 | D2: 0.000108371 | E2: 2.04503 | F2: 3.40004 | G2: 4.06155 | H2: 4.43856 | I2: 1.35501 | J2: 2.01652 | K2: 2.39353 | L2: 0.66151 | M2: 1.03852 | N2: 0.37701 | O2: 0.62097452 | P2: -0.76512384 | Q2: -1.8421704
A3: 1.2376625e+18 | B3: 236.2748 | C3: 35.890829 | D3: 0.006308075 | E3: 0.72406 | F3: 0.86827 | G3: 0.81862 | H3: 0.8866 | I3: 0.14421 | J3: 0.09456 | K3: 0.16254 | L3: -0.04965 | M3: 0.01833 | N3: 0.06798 | O3: 7.0133944 | P3: 1.2791033 | Q3: -0.11628536
A4: 1.2376625e+18 | B4: 236.21743 | C4: 36.479334 | D4: 0.01116591 | E4: 1.11507 | F4: 1.5368 | G4: 1.69315 | H4: 1.81019 | I4: 0.42173 | J4: 0.57808 | K4: 0.69512 | L4: 0.15635 | M4: 0.27339 | N4: 0.11704 | O4: 5.3488902 | P4: 0.84979636 | Q4: 1.1591594
A5: 1.2376625e+18 | B5: 236.4412 | C5: 36.028097 | D5: 0.01141854 | E5: 1.0158 | F5: 1.36323 | G5: 1.57702 | H5: 1.6244 | I5: 0.34743 | J5: 0.56122 | K5: 0.6086 | L5: 0.21379 | M5: 0.26117 | N5: 0.04738 | O5: 5.6023263 | P5: 0.85312964 | Q5: 0.49564519
A6: 1.2376625e+18 | B6: 236.2044 | C6: 36.563143 | D6: 0.03872261 | E6: 1.32078 | F6: 1.82759 | G6: 2.0776 | H6: 2.21528 | I6: 0.50681 | J6: 0.75682 | K6: 0.8945 | L6: 0.25001 | M6: 0.38769 | N6: 0.13768 | O6: 4.6458071 | P6: 0.5996452 | Q6: 1.3190431
A7: 1.2376623e+18 | B7: 235.95322 | C7: 35.634052 | D7: 0.04851187 | E7: 1.10182 | F7: 1.51008 | G7: 1.77106 | H7: 1.9507 | I7: 0.40826 | J7: 0.66924 | K7: 0.84888 | L7: 0.26098 | M7: 0.44062 | N7: 0.17964 | O7: 4.9600853 | P7: 0.81208754 | Q7: -1.5188748
A8: 1.2376615e+18 | B8: 236.42283 | C8: 35.660888 | D8: 0.05498169 | E8: 1.50337 | F8: 2.0518 | G8: 2.31401 | H8: 2.53843 | I8: 0.54843 | J8: 0.81064 | K8: 1.03506 | L8: 0.26221 | M8: 0.48663 | N8: 0.22442 | O8: 4.1532791 | P8: 0.13832046 | Q8: -0.46289065
A9: 1.2376615e+18 | B9: 236.4388 | C9: 35.659931 | D9: 0.0551876 | E9: 1.99307 | F9: 2.90228 | G9: 3.34674 | H9: 3.68612 | I9: 0.90921 | J9: 1.35367 | K9: 1.69305 | L9: 0.44446 | M9: 0.78384 | N9: 0.33938 | O9: 2.1630148 | P9: -0.61369314 | Q9: -0.51144385
A10: 1.2376615e+18 | B10: 236.4388 | C10: 35.659931 | D10: 0.05523921 | E10: 1.99307 | F10: 2.90228 | G10: 3.34674 | H10: 3.68612 | I10: 0.90921 | J10: 1.35367 | K10: 1.69305 | L10: 0.44446 | M10: 0.78384 | N10: 0.33938 | O10: 2.1629492 | P10: -0.61365492 | Q10: -0.51144821
A11: 1.2376625e+18 | B11: 236.28331 | C11: 36.184873 | D11: 0.05844347 | E11: 1.33689 | F11: 1.95728 | G11: 2.29236 | H11: 2.49538 | I11: 0.62039 | J11: 0.95547 | K11: 1.15849 | L11: 0.33508 | M11: 0.5381 | N11: 0.20302 | O11: 3.9363919 | P11: 0.5325215 | Q11: 0.50461928
A12: 1.2376625e+18 | B12: 236.24143 | C12: 36.06883 | D12: 0.0599989 | E12: 1.88341 | F12: 2.76878 | G12: 3.18127 | H12: 3.52614 | I12: 0.88537 | J12: 1.29786 | K12: 1.64273 | L12: 0.41249 | M12: 0.75736 | N12: 0.34487 | O12: 2.3653092 | P12: -0.30213224 | Q12: 0.100344
A13: 1.2376625e+18 | B13: 236.261 | C13: 36.156339 | D13: 0.06039927 | E13: 1.95959 | F13: 2.84952 | G13: 3.27597 | H13: 3.6085 | I13: 0.88993 | J13: 1.31638 | K13: 1.64891 | L13: 0.42645 | M13: 0.75898 | N13: 0.33253 | O13: 2.2866507 | P13: -0.4068743 | Q13: 0.36049119
... A18: 1.2376625e+18 | B18: 236.16559 | C18: 36.137926 | D18: 0.06155551 | E18: 1.83447 | F18: 2.63866 | G18: 2.99538 | H18: 3.26296 | I18: 0.80419 | J18: 1.16091 | K18: 1.42849 | L18: 0.35672 | M18: 0.6243 | N18: 0.26758 | O18: 2.9739891 | P18: -0.28110182 | Q18: 0.12431254
A19: 1.2376625e+18 | B19: 236.38393 | C19: 36.077117 | D19: 0.06209526 | E19: 1.0198 | F19: 1.38881 | G19: 1.65753 | H19: 1.78982 | I19: 0.36901 | J19: 0.63773 | K19: 0.77002 | L19: 0.26872 | M19: 0.40101 | N19: 0.13229 | O19: 5.0795057 | P19: 1.0332072 | Q19: 0.49969714 | AA19: PC1 | AB19: 2.005-3.24
A20: 1.2376625e+18 | B20: 236.19078 | C20: 36.079215 | D20: 0.06218404 | E20: 1.78613 | F20: 2.62508 | G20: 3.04295 | H20: 3.33189 | I20: 0.83895 | J20: 1.25682 | K20: 1.54576 | L20: 0.41787 | M20: 0.70681 | N20: 0.28894 | O20: 2.6853355 | P20: -0.18180458 | Q20: 0.012917646 | AA20: PC2 | AB20: min 0.7-0.12
A21: 1.2376625e+18 | B21: 236.18645 | C21: 36.129856 | D21: 0.06279468 | E21: 1.97194 | F21: 2.87787 | G21: 3.30577 | H21: 3.64975 | I21: 0.90593 | J21: 1.33383 | K21: 1.67781 | L21: 0.4279 | M21: 0.77188 | N21: 0.34398 | O21: 2.2194442 | P21: -0.42391793 | Q21: 0.13385867 | AA21: PC3 | AB21: 2- min 1.2
A22: 1.2376625e+18 | B22: 236.09999 | C22: 36.135241 | D22: 0.06282794 | E22: 1.73946 | F22: 2.53892 | G22: 2.92469 | H22: 3.15415 | I22: 0.79946 | J22: 1.18523 | K22: 1.41469 | L22: 0.38577 | M22: 0.61523 | N22: 0.22946 | O22: 3.0852718 | P22: -0.15872727 | Q22: -0.039907715
A23: 1.2376625e+18 | B23: 236.2503 | C23: 36.110351 | D23: 0.06285614 | E23: 1.86984 | F23: 2.79216 | G23: 3.22688 | H23: 3.6159 | I23: 0.92232 | J23: 1.35704 | K23: 1.74606 | L23: 0.43472 | M23: 0.82374 | N23: 0.38902 | O23: 2.0898411 | P23: -0.21975288 | Q23: 0.21773419
A24: 1.2376625e+18 | B24: 236.19515 | C24: 35.950268 | D24: 0.06286892 | E24: 2.01011 | F24: 2.89555 | G24: 3.31256 | H24: 3.61431 | I24: 0.88544 | J24: 1.30245 | K24: 1.6042 | L24: 0.41701 | M24: 0.71876 | N24: 0.30175 | O24: 2.4079914 | P24: -0.58682915 | Q24: -0.29745348
A25: 1.2376625e+18 | B25: 236.24133 | C25: 36.188203 | D25: 0.06332173 | E25: 1.82233 | F25: 2.66788 | G25: 3.06453 | H25: 3.354 | I25: 0.84555 | J25: 1.2422 | K25: 1.53167 | L25: 0.39665 | M25: 0.68612 | N25: 0.28947 | O25: 2.6887482 | P25: -0.22397559 | Q25: 0.39661002
A26: 1.2376625e+18 | B26: 236.23274 | C26: 36.138508 | D26: 0.06371365 | E26: 1.92347 | F26: 2.77902 | G26: 3.16442 | H26: 3.46772 | I26: 0.85555 | J26: 1.24095 | K26: 1.54425 | L26: 0.3854 | M26: 0.6887 | N26: 0.3033 | O26: 2.5968655 | P26: -0.39216379 | Q26: 0.26243286
A27: 1.2376625e+18 | B27: 236.64889 | C27: 36.16354 | D27: 0.06372982 | E27: 1.01871 | F27: 1.45528 | G27: 1.77727 | H27: 1.97137 | I27: 0.43657 | J27: 0.75856 | K27: 0.95266 | L27: 0.32199 | M27: 0.51609 | N27: 0.1941 | O27: 4.5339958 | P27: 1.1184447 | Q27: 1.2642427
A28: 1.2376625e+18 | B28: 236.09188 | C28: 36.105321 | D28: 0.06383671 | E28: 1.89928 | F28: 2.81325 | G28: 3.23922 | H28: 3.57214 | I28: 0.91397 | J28: 1.33994 | K28: 1.67286 | L28: 0.42597 | M28: 0.75889 | N28: 0.33292 | O28: 2.3092205 | P28: -0.33368336 | Q28: -0.1387675
A29: 1.2376625e+18 | B29: 236.44992 | C29: 35.928752 | D29: 0.06386434 | E29: 1.60395 | F29: 2.44741 | G29: 2.8331 | H29: 3.13723 | I29: 0.84346 | J29: 1.22915 | K29: 1.53328 | L29: 0.38569 | M29: 0.68982 | N29: 0.30413 | O29: 2.8130106 | P29: 0.04563776 | Q29: 0.17838772
A30: 1.2376625e+18 | B30: 235.8664 | C30: 36.370778 | D30: 0.06389388 | E30: 2.00953 | F30: 2.92309 | G30: 3.36833 | H30: 3.67713 | I30: 0.91356 | J30: 1.3588 | K30: 1.6676 | L30: 0.44524 | M30: 0.75404 | N30: 0.3088 | O30: 2.2688884 | P30: -0.43651925 | Q30: 0.04834712
A31: 1.2376625e+18 | B31: 236.17264 | C31: 36.06545 | D31: 0.06399604 | E31: 1.82036 | F31: 2.70346 | G31: 3.12178 | H31: 3.42206 | I31: 0.8831 | J31: 1.30142 | K31: 1.6017 | L31: 0.41832 | M31: 0.7186 | N31: 0.30028 | O31: 2.5358431 | P31: -0.25234372 | Q31: -0.06980296
A32: 1.2376625e+18 | B32: 236.24023 | C32: 36.020008 | D32: 0.06411387 | E32: 1.8021 | F32: 2.66513 | G32: 3.06724 | H32: 3.36483 | I32: 0.86303 | J32: 1.26514 | K32: 1.56273 | L32: 0.40211 | M32: 0.6997 | N32: 0.29759 | O32: 2.6383699 | P32: -0.24005298 | Q32: -0.033613335
A33: 1.2376615e+18 | B33: 236.06752 | C33: 35.897172 | D33: 0.06413121 | E33: 1.82611 | F33: 2.6731 | G33: 3.08937 | H33: 3.37383 | I33: 0.84699 | J33: 1.26326 | K33: 1.54772 | L33: 0.41627 | M33: 0.70073 | N33: 0.28446 | O33: 2.6954267 | P33: -0.30465829 | Q33: -0.70603279
... A475: 1.2376625e+18 | B475: 235.98914 | C475: 36.504567 | D475: 1.530724 | E475: 1.52142 | F475: 2.81548 | G475: 3.82687 | H475: 4.65748 | I475: 1.29406 | J475: 2.30545 | K475: 3.13606 | L475: 1.01139 | M475: 1.842 | N475: 0.83061 | O475: -3.3535067 | P475: 2.2273967 | Q475: 0.41457565

Sheet 3 pc plot
A1: objID | B1: ra | C1: dec | D1: z | E1: u-g | F1: u-r | G1: u-i | H1: u-z | I1: g-r | J1: g-i | K1: g-z | L1: r-i | M1: r-z | N1: i-z | O1: PC(1) | P1: PC(2) | Q1: PC(3) | R1: Rproj (m) | S1: Vrad (m/s)
A2: 1.2376615e+18 | B2: 236.4388 | C2: 35.659931 | D2: 0.0551876 | E2: 1.99307 | F2: 2.90228 | G2: 3.34674 | H2: 3.68612 | I2: 0.90921 | J2: 1.35367 | K2: 1.69305 | L2: 0.44446 | M2: 0.78384 | N2: 0.33938 | O2: 2.1630148 | P2: -0.61369314 | Q2: -0.51144385 | R2: 2.5682362 | S2: 16556.28
